<?xml version="1.0"?>
<robot name="2dof_planar_robot">

  <link name="base_link">
    <visual>
      <origin xyz="0 0 0" rpy="0 0 0"/>
      <geometry>
        <box size="0.1 0.1 0.1"/>
      </geometry>
      <material name="black">
        <color rgba="0.1 0.1 0.1 1"/>
      </material>
    </visual>
  </link>

  <link name="link1">
    <visual>
      <origin xyz="0.5 0 0" rpy="0 0 0"/>
      <geometry>
        <box size="1 0.05 0.05"/>
      </geometry>
      <material name="red">
        <color rgba="1 0 0 1"/>
      </material>
    </visual>
  </link>

  <link name="link2">
    <visual>
      <origin xyz="0.5 0 0" rpy="0 0 0"/>
      <geometry>
        <box size="1 0.05 0.05"/>
      </geometry>
      <material name="green">
        <color rgba="0 1 0 1"/>
      </material>
    </visual>
  </link>

  <link name="ee">
    <visual>
      <origin xyz="0 0 0" rpy="0 0 0"/>
      <geometry>
        <sphere radius="0.05"/>
      </geometry>
      <material name="blue">
        <color rgba="0 0 1 1"/>
      </material>
    </visual>
  </link>

  <joint name="joint1" type="revolute">
    <parent link="base_link"/>
    <child link="link1"/>
    <origin xyz="0 0 0" rpy="0 0 0"/>
    <axis xyz="0 0 1"/>
    <limit lower="-3.14" upper="3.14" effort="10" velocity="3.14"/>
  </joint>

  <joint name="joint2" type="revolute">
    <parent link="link1"/>
    <child link="link2"/>
    <origin xyz="1 0 0" rpy="0 0 0"/> <!-- link1 is 1m long -->
    <axis xyz="0 0 1"/>
    <limit lower="-3.14" upper="3.14" effort="10" velocity="3.14"/>
  </joint>

  <joint name="ee_fixed" type="fixed">
    <parent link="link2"/>
    <child link="ee"/>
    <origin xyz="1 0 0" rpy="0 0 0"/> <!-- link2 is 1m long -->
  </joint>

</robot>
